Workbook

Sheet M-INDEX
A1: 🏛 QUADRUM v1.0: Sistema Integral de Auditoría y Planificación (SIAP-ICPI) · Desarrollado bajo el Protocolo de Integridad Forense ALFARO VIRTUS · GAD Municipal Montecristi · Plan Bicentenario 2023-2027
A2: ◉ INICIO | G2: =HYPERLINK("#'M6-FEDS'!A1","M6") -> M6 | H2: =HYPERLINK("#'M7-PROSP'!A1","M7") -> M7 | I2: =HYPERLINK("#'DATA-POA'!A1","DATA-POA") -> DATA-POA | J2: =HYPERLINK("#'DATA-CNE'!A1","DATA-CNE") -> DATA-CNE | K2: =HYPERLINK("#'DATA-ORG'!A1","DATA-ORG") -> DATA-ORG | L2: =HYPERLINK("#'M-DASHBOARD'!A1","DASH") -> DASH
A3: GAD: | B3: Municipal de Montecristi | D3: PDOT: | E3: Bicentenario 2023-2027
A4: Provincia: | B4: Manabí, Ecuador | D4: Metas: | E4: 20 (muestra estratégica)
A5: Período: | B5: 2023-2027 | D5: Presupuesto: | E5: 32990353
A6: Versión: | B6: SIAP-ICPI v1.0 | D6: Hojas: | E6: 38 módulos activos | F6: 38 módulos activos
A8: # | B8: GRUPO | C8: HOJA | D8: DESCRIPCIÓN | E8: CAPA SIAP-ICPI | F8: IR
A9: 1 | B9: Ejecutiva | C9: =HYPERLINK("#'M-DASHBOARD'!A1","M-DASHBOARD") -> M-DASHBOARD | D9: Panel ejecutivo ICPI global · semáforos · KPIs · ejes PDOT | E9: ❺ SALIDA · Panel ejecutivo | F9: =HYPERLINK("#'M-DASHBOARD'!A1","Ir →") -> Ir →
A10: 2 | B10: Estratégica | C10: =HYPERLINK("#'M-TECH-GAD'!A1","M-TECH-GAD") -> M-TECH-GAD | D10: Configuración institucional GAD Montecristi | E10: ⬡ CONTROL · Configuración GAD | F10: =HYPERLINK("#'M-TECH-GAD'!A1","Ir →") -> Ir →
A11: 3 | B11: Estratégica | C11: =HYPERLINK("#'M-TECH-PARAMS'!A1","M-TECH-PARAMS") -> M-TECH-PARAMS | D11: Parámetros globales · umbrales · constantes del sistema | E11: ⬡ CONTROL · Parámetros | F11: =HYPERLINK("#'M-TECH-PARAMS'!A1","Ir →") -> Ir →
A12: 4 | B12: Auditoría | C12: =HYPERLINK("#'M1-ITME'!A1","M1-ITME") -> M1-ITME | D12: Catálogo documental PDOT · universo n=35 · muestra n=20 | E12: ❶ BASE PDOT · Catálogo | F12: =HYPERLINK("#'M1-ITME'!A1","Ir →") -> Ir →
A13: 5 | B13: Estratégica | C13: =HYPERLINK("#'M2-PDOT'!A1","M2-PDOT") -> M2-PDOT | D13: Base primaria operativa · 20 metas · Pi · Ri · Vi · Ti · Ci · Marco legal COOTAD | E13: ❶ BASE PDOT · Operativa | F13: =HYPERLINK("#'M2-PDOT'!A1","Ir →") -> Ir →
A14: 6 | B14: Estratégica | C14: =HYPERLINK("#'M2-PLAN-Pi'!A1","M2-PLAN-Pi") -> M2-PLAN-Pi | D14: Ponderación Pi · presupuesto PDOT 2023-2027 · ΣPi=1.000 | E14: ❶ BASE PDOT · Ponderación Pi | F14: =HYPERLINK("#'M2-PLAN-Pi'!A1","Ir →") -> Ir →
A15: 7 | B15: Auditoría | C15: =HYPERLINK("#'DATA-TFR'!A1","DATA-TFR") -> DATA-TFR | D15: Tabla de Factores de Relevancia · Ri por competencia COOTAD | E15: ❶ BASE PDOT · Relevancia Ri | F15: =HYPERLINK("#'DATA-TFR'!A1","Ir →") -> Ir →
A16: 8 | B16: Auditoría | C16: =HYPERLINK("#'M3-MAO'!A1","M3-MAO") -> M3-MAO | D16: Matriz de Atribución Orgánica · factor Ci por Dirección GAD | E16: ❶ BASE PDOT · Atribución Ci | F16: =HYPERLINK("#'M3-MAO'!A1","Ir →") -> Ir →
A17: 9 | B17: Cálculo | C17: =HYPERLINK("#'DATA-SSC'!A1","DATA-SSC") -> DATA-SSC | D17: Subíndice Social Complementario · escalabilidad institucional | E17: ❶ BASE PDOT · Escalabilidad | F17: =HYPERLINK("#'DATA-SSC'!A1","Ir →") -> Ir →
A18: 10 | B18: Auditoría | C18: =HYPERLINK("#'M4-AUDIT'!A1","M4-AUDIT") -> M4-AUDIT | D18: Matriz Auditoría Documental · Vi · Ei · Ti · n=20 metas PDOT | E18: ❷ AUDITORÍA · MAD | F18: =HYPERLINK("#'M4-AUDIT'!A1","Ir →") -> Ir →
A19: 11 | B19: Auditoría | C19: =HYPERLINK("#'DATA-MEC'!A1","DATA-MEC") -> DATA-MEC | D19: Matriz de Evidencia y Cadena de Custodia (§3.4.3 SIAP-ICPI) | E19: ❷ AUDITORÍA · Cadena custodia | F19: =HYPERLINK("#'DATA-MEC'!A1","Ir →") -> Ir →
A20: 12 | B20: Ingesta | C20: =HYPERLINK("#'DATA-CED'!A1","DATA-CED") -> DATA-CED | D20: Cédulas Presupuestarias eSIGEF · Ti = Devengado ÷ Codificado | E20: ❖ INGESTA · Ejecución Ti | F20: =HYPERLINK("#'DATA-CED'!A1","Ir →") -> Ir →
A21: 13 | B21: Ingesta | C21: =HYPERLINK("#'DATA-POA'!A1","DATA-POA") -> DATA-POA | D21: Alineación PAC/POA 2023-2025 · brechas de activación por meta | E21: ❖ INGESTA · POA | F21: =HYPERLINK("#'DATA-POA'!A1","Ir →") -> Ir →
A22: 14 | B22: Ingesta | C22: =HYPERLINK("#'DATA-PAC'!A1","DATA-PAC") -> DATA-PAC | D22: Plan Anual de Contratación · fuente SERCOP · por meta PDOT | E22: ❖ INGESTA · PAC SERCOP | F22: =HYPERLINK("#'DATA-PAC'!A1","Ir →") -> Ir →
A23: 15 | B23: Cálculo | C23: =HYPERLINK("#'M5-ICPI'!A1","M5-ICPI") -> M5-ICPI | D23: Motor Central ICPI = Σ(Pi×Ri×Vi×Ei×Ti×Ci) ÷ Σ(Pi×Ri) | E23: ❸ CÁLCULO · Motor ICPI | F23: =HYPERLINK("#'M5-ICPI'!A1","Ir →") -> Ir →
A24: 16 | B24: Cálculo | C24: =HYPERLINK("#'DATA-RESULTADOS'!A1","DATA-RESULTADOS") -> DATA-RESULTADOS | D24: Resultados consolidados ICPI · semáforo AVEP · brecha vs 2027 · Dashboard resumen PDOT | E24: ❸ CÁLCULO · Resultado ICPI + Dashboard | F24: =HYPERLINK("#'DATA-RESULTADOS'!A1","Ir →") -> Ir →
A25: 17 | B25: Cálculo | C25: =HYPERLINK("#'SUPPORT-INTERP'!A1","SUPPORT-INTERP") -> SUPPORT-INTERP | D25: Interpretación cualitativa · escala AVEP 5 niveles | E25: ❸ CÁLCULO · Interpretación AVEP | F25: =HYPERLINK("#'SUPPORT-INTERP'!A1","Ir →") -> Ir →
A26: 18 | B26: Cálculo | C26: =HYPERLINK("#'VALID-CST'!A1","VALID-CST") -> VALID-CST | D26: Validación de consistencia melógica y flujos de datos | E26: ❹ VALIDACIÓN · Consistencia | F26: =HYPERLINK("#'VALID-CST'!A1","Ir →") -> Ir →
A27: 19 | B27: Cálculo | C27: =HYPERLINK("#'M7-PROSP'!A1","M7-PROSP") -> M7-PROSP | D27: Análisis analítico cruzado de variables SIAP-ICPI | E27: ❹ VALIDACIÓN · Análisis cruzado | F27: =HYPERLINK("#'M7-PROSP'!A1","Ir →") -> Ir →
A28: 20 | B28: Cálculo | C28: =HYPERLINK("#'VALID-MVCI'!A1","VALID-MVCI") -> VALID-MVCI | D28: Matriz de Verificación de Coherencia Interna · 20/20 | E28: ❹ VALIDACIÓN · Coherencia interna | F28: =HYPERLINK("#'VALID-MVCI'!A1","Ir →") -> Ir →
A29: 21 | B29: Cálculo | C29: =HYPERLINK("#'DATA-EJES'!A1","DATA-EJES") -> DATA-EJES | D29: ICPI desagregado por eje estratégico PDOT · 5 ejes | E29: ❹ VALIDACIÓN · ICPI por eje | F29: =HYPERLINK("#'DATA-EJES'!A1","Ir →") -> Ir →
A30: 22 | B30: Cálculo | C30: =HYPERLINK("#'VALID-SENS'!A1","VALID-SENS") -> VALID-SENS | D30: Análisis de sensibilidad · Vi=0→Vi=1 · Δ máx. +20.6pp | E30: ❹ VALIDACIÓN · Sensibilidad | F30: =HYPERLINK("#'VALID-SENS'!A1","Ir →") -> Ir →
A31: 23 | B31: Ejecutiva | C31: =HYPERLINK("#'DATA-BRECHA'!A1","DATA-BRECHA") -> DATA-BRECHA | D31: Análisis de Brecha Programática · ICPI vs Meta PDOT 2027 | E31: ❖ EJECUTIVA · Brecha ICPI | F31: =HYPERLINK("#'DATA-BRECHA'!A1","Ir →") -> Ir →
A32: 24 | B32: Ejecutiva | C32: =HYPERLINK("#'DATA-ORG'!A1","DATA-ORG") -> DATA-ORG | D32: Estructura Orgánica GAD · auditoría Ci vs Estatuto Orgánico | E32: ❖ EJECUTIVA · Estructura orgánica | F32: =HYPERLINK("#'DATA-ORG'!A1","Ir →") -> Ir →
A33: 25 | B33: Cálculo | C33: =HYPERLINK("#'M6-FEDS'!A1","M6-FEDS") -> M6-FEDS | D33: Estrategia Desarrollo Sostenible · IED servidores públicos | E33: ❖ CÁLCULO · IED desarrollo | F33: =HYPERLINK("#'M6-FEDS'!A1","Ir →") -> Ir →
A34: 26 | B34: Ejecutiva | C34: =HYPERLINK("#'SUPPORT-EVALDIR'!A1","SUPPORT-EVALDIR") -> SUPPORT-EVALDIR | D34: Evaluación semestral directivos LOSEP · escala 5 niveles | E34: ❻ EVALUACIÓN · Directivos | F34: =HYPERLINK("#'SUPPORT-EVALDIR'!A1","Ir →") -> Ir →
A35: 27 | B35: Ejecutiva | C35: =HYPERLINK("#'SUPPORT-SEM'!A1","SUPPORT-SEM") -> SUPPORT-SEM | D35: Cortes semestrales S1/S2 · SIITH-MDT · 12 directivos GAD | E35: ❻ EVALUACIÓN · Cortes SIITH | F35: =HYPERLINK("#'SUPPORT-SEM'!A1","Ir →") -> Ir →
A36: 28 | B36: Cálculo | C36: =HYPERLINK("#'DATA-ITAM'!A1","DATA-ITAM") -> DATA-ITAM | D36: Índice Transparencia Activa Municipal · LOTAIP Art.7 · 84% | E36: ⬡ TRANSVERSAL · ITAM | F36: =HYPERLINK("#'DATA-ITAM'!A1","Ir →") -> Ir →
A37: 29 | B37: Ejecutiva | C37: =HYPERLINK("#'SUPPORT-SIL'!A1","SUPPORT-SIL") -> SUPPORT-SIL | D37: Exportación SIL SIGAD · portal Planifica Ecuador · mensual día 5 | E37: ❼ SALIDA/SIL · Exportación | F37: =HYPERLINK("#'SUPPORT-SIL'!A1","Ir →") -> Ir →
A38: 30 | B38: Ejecutiva | C38: =HYPERLINK("#'SUPPORT-ALERT'!A1","SUPPORT-ALERT") -> SUPPORT-ALERT | D38: Alertas automáticas · 14 alertas · 4 niveles COOTAD + LOSEP | E38: ❼ SALIDA/SIL · Alertas | F38: =HYPERLINK("#'SUPPORT-ALERT'!A1","Ir →") -> Ir →
A39: 31 | B39: Auditoría | C39: =HYPERLINK("#'VALID-VER'!A1","VALID-VER") -> VALID-VER | D39: Matriz de Control Documental · 8 fuentes verificadas por meta | E39: ❷ AUDITORÍA · Control documental | F39: =HYPERLINK("#'VALID-VER'!A1","Ir →") -> Ir →
A40: 32 | B40: Ingesta | C40: =HYPERLINK("#'DATA-CPCCS'!A1","DATA-CPCCS") -> DATA-CPCCS | D40: Anexo CPCCS · participación ciudadana por meta PDOT | E40: ⬡ TRANSVERSAL · CPCCS | F40: =HYPERLINK("#'DATA-CPCCS'!A1","Ir →") -> Ir →
A41: 33 | B41: Ingesta | C41: =HYPERLINK("#'DATA-CNE'!A1","DATA-CNE") -> DATA-CNE | D41: Anexo CNE · evidencias procesos electorales por meta PDOT | E41: ⬡ TRANSVERSAL · CNE | F41: =HYPERLINK("#'DATA-CNE'!A1","Ir →") -> Ir →
...

Sheet M-DASHBOARD
A1: QUADRUM v1.0: Sistema Integral de Auditoría y Planificación (SIAP-ICPI) · Desarrollado bajo el Protocolo de Integridad Forense ALFARO VIRTUS · GAD Municipal Montecristi
A2: =HYPERLINK("#'M-INDEX'!A1","⌂ INDICE") -> ⌂ INDICE | F2: =HYPERLINK("#'M5-ICPI'!A1","M5") -> M5 | G2: =HYPERLINK("#'M6-FEDS'!A1","M6") -> M6 | H2: =HYPERLINK("#'M7-PROSP'!A1","M7") -> M7 | I2: =HYPERLINK("#'DATA-POA'!A1","DATA-POA") -> DATA-POA | J2: =HYPERLINK("#'DATA-CNE'!A1","DATA-CNE") -> DATA-CNE | K2: =HYPERLINK("#'DATA-ORG'!A1","DATA-ORG") -> DATA-ORG | L2: =HYPERLINK("#'M-DASHBOARD'!A1","DASH") -> DASH
A3: ="Capa: Documentación > Panel Ejecutivo ICPI · ICPI Global = "&TEXT('M5-ICPI'!G29,"0,00")&"% · "&'DATA-RESULTADOS'!B8&" · Actualización: mensual" -> Capa: Documentación > Panel Ejecutivo ICPI · ICPI Global = 38,28% · Transición Crítica 🟡 · Actualización: mensual | F3: ICM Oficial SIGAD (%) | G3: 92.25 | H3: 100
A4: ◉ ICPI GLOBAL — Principio de Invariabilidad Algorítmica | C4: =TEXT('M5-ICPI'!G29,"0,00")&" %" -> 38,28 % | D4: =IF('M5-ICPI'!G29>=85,"🔵 EXCELENCIA",IF('M5-ICPI'!G29>=70,"🟢 GESTIÓN POR MANDATO",IF('M5-ICPI'!G29>=40,"🟠 TRANSICIÓN CRÍTICA",IF('M5-ICPI'!G29>=20,"🔴 GESTIÓN POR OCURRENCIA","⬛ RUPTURA TOTAL")))) -> 🔴 GESTIÓN POR OCURRENCIA | E4: ="Brecha vs ICM: "&TEXT('M5-ICPI'!G29-92.25,"0,00")&" pp · Meta 2027: 92,5%" -> Brecha vs ICM: -53,97 pp · Meta 2027: 92,5% | F4: Ejecución completa Vi=1,Ti=1 (n) | G4: =COUNTIFS('M5-ICPI'!E5:E24,1,'M5-ICPI'!F5:F24,">="&0.8) -> 5 | H4: 20
A5: ◉ INDICADORES CLAVE · KPIs del Sistema SIAP-ICPI · Base: PDOT Plan Bicentenario 2023-2027 | F5: Metas con Evidencia Vi=1 (%) | G5: =COUNTIF('M5-ICPI'!E5:E24,1)/20*100 -> 75 | H5: 100
A6: KPI | B6: VALOR ACTUAL | C6: BARRA DE AVANCE | E6: CONTEXTO / FUENTE | F6: 🌐 ITAM Global — Transp. (%) | G6: ='DATA-ITAM'!B6*100 -> 78 | H6: 100
A7: ICPI GLOBAL (%) | B7: =TEXT('M5-ICPI'!G29,"0,00")&" %" -> 38,28 % | C7: =REPT("█",ROUND('M5-ICPI'!G29/5,0))&REPT("░",20-ROUND('M5-ICPI'!G29/5,0))&" "&TEXT('M5-ICPI'!G29,"0,00")&" %" -> ████████░░░░░░░░░░░░ 38,28 % | E7: ="Meta: 92,5 % · "&IF('M5-ICPI'!G29>=85,"🔵 EXCELENCIA",IF('M5-ICPI'!G29>=70,"🟢 GESTIÓN POR MANDATO",IF('M5-ICPI'!G29>=40,"🟠 TRANSICIÓN CRÍTICA",IF('M5-ICPI'!G29>=20,"🔴 GESTIÓN POR OCURRENCIA","⬛ RUPTURA TOTAL"))))&" · Motor ICPI" -> Meta: 92,5 % · 🔴 GESTIÓN POR OCURRENCIA · Motor ICPI | F7: Brecha de Integridad ICPI vs ICM (pp) | G7: =ABS('M5-ICPI'!G29-92.25) -> 53.966986 | H7: 100
A8: Semáforo ICPI | B8: =IF('M5-ICPI'!G29>=85,"🔵 EXCELENCIA",IF('M5-ICPI'!G29>=70,"🟢 GESTIÓN POR MANDATO",IF('M5-ICPI'!G29>=40,"🟠 TRANSICIÓN CRÍTICA",IF('M5-ICPI'!G29>=20,"🔴 GESTIÓN POR OCURRENCIA","⬛ RUPTURA TOTAL")))) -> 🔴 GESTIÓN POR OCURRENCIA | C8: ="Nivel "&IF('M5-ICPI'!G29>=85,"1",IF('M5-ICPI'!G29>=70,"2",IF('M5-ICPI'!G29>=40,"3",IF('M5-ICPI'!G29>=20,"4","5"))))&" de 5 — §3.7 SIAP-ICPI" -> Nivel 4 de 5 — §3.7 SIAP-ICPI | E8: Ver INTERP para tabla de rangos
A9: ICM Oficial SIGAD (%) | B9: =TEXT(92.25,"0,00")&" %" -> 92,25 % | C9: =REPT("█",ROUND(92.25/5,0))&REPT("░",20-ROUND(92.25/5,0))&" "&TEXT(92.25,"0,00")&" %" -> ██████████████████░░ 92,25 % | E9: ="Mandato OK · SIGAD · Brecha integridad: "&TEXT('M5-ICPI'!G29-92.25,"0,00")&" pp" -> Mandato OK · SIGAD · Brecha integridad: -53,97 pp
A10: Brecha de Integridad (pp) | B10: =TEXT('M5-ICPI'!G29-92.25,"0,00")&" pp" -> -53,97 pp | C10: =REPT("█",ROUND(ABS('M5-ICPI'!G29-92.25)/5,0))&REPT("░",20-ROUND(ABS('M5-ICPI'!G29-92.25)/5,0))&" "&TEXT('M5-ICPI'!G29-92.25,"0,00")&" pp" -> ███████████░░░░░░░░░ -53,97 pp | E10: Brecha ICPI vs ICM · Ver BI · Prioridad máxima | F10: Eje | G10: ICPI (%)
A11: Metas con Evidencia (Vi=1) | B11: =COUNTIF('M5-ICPI'!E5:E24,1)&" / 20 ("&TEXT(COUNTIF('M5-ICPI'!E5:E24,1)/20,"0%")&")" -> 15 / 20 (75%) | C11: =REPT("█",ROUND(COUNTIF('M5-ICPI'!E5:E24,1),0))&REPT("░",20-ROUND(COUNTIF('M5-ICPI'!E5:E24,1),0))&" "&COUNTIF('M5-ICPI'!E5:E24,1)&" / 20" -> ███████████████░░░░░ 15 / 20 | E11: Vi=1 verificadas documentalmente · Ver MAD | F11: TERRITORIAL | G11: ='DATA-EJES'!D4 -> 25.761436
A12: Ejecución Completa (Vi=1,Ti=1) | B12: =COUNTIFS('M5-ICPI'!E5:E24,1,'M5-ICPI'!F5:F24,">="&0.8)&" / 20 ("&TEXT(COUNTIFS('M5-ICPI'!E5:E24,1,'M5-ICPI'!F5:F24,">="&0.8)/20,"0%")&")" -> 5 / 20 (25%) | C12: =REPT("█",COUNTIFS('M5-ICPI'!E5:E24,1,'M5-ICPI'!F5:F24,">="&0.8))&REPT("░",20-COUNTIFS('M5-ICPI'!E5:E24,1,'M5-ICPI'!F5:F24,">="&0.8))&" "&COUNTIFS('M5-ICPI'!E5:E24,1,'M5-ICPI'!F5:F24,">="&0.8)&" / 20" -> █████░░░░░░░░░░░░░░░ 5 / 20 | E12: Vi=1 y Ti≥80% · Ver MAD · Prioridad POA 2025 | F12: SOCIAL | G12: ='DATA-EJES'!D5 -> 51.686758
A13: 🌐 ITAM — Transparencia Activa | B13: =TEXT('DATA-ITAM'!B6*100,"0,0")&" %" -> 78,0 % | C13: =REPT("█",ROUND('DATA-ITAM'!B6*20,0))&REPT("░",20-ROUND('DATA-ITAM'!B6*20,0))&" "&TEXT('DATA-ITAM'!B6*100,"0,0")&" %" -> ████████████████░░░░ 78,0 % | E13: LOTAIP Art.7 · Ver ITAM · Meta: 100% | F13: AMBIENTAL | G13: ='DATA-EJES'!D6 -> 44.931664
A14: ⊕ ICPI POR EJE ESTRATÉGICO · Distribución del desempeño por sistema PDOT · 5 ejes Plan Bicentenario 2023-2027 | F14: ECONÓMICO | G14: ='DATA-EJES'!D7 -> 70
A15: EJE ESTRATÉGICO | B15: ICPI (%) | C15: BARRA DE AVANCE | D15: PESO EN MUESTRA | E15: ESTADO | F15: INSTITUCIONAL | G15: ='DATA-EJES'!D8 -> 60.15129
A16: TERRITORIAL | B16: =TEXT('DATA-EJES'!D4,"0,0")&" %" -> 25,8 % | C16: =REPT("█",ROUND('DATA-EJES'!D4/5,0))&REPT("░",20-ROUND('DATA-EJES'!D4/5,0))&" "&TEXT('DATA-EJES'!D4,"0,0")&" %" -> █████░░░░░░░░░░░░░░░ 25,8 % | D16: =TEXT(SUMIF('M5-ICPI'!B5:B24,"TERRITORIAL",'M5-ICPI'!H5:H24)/SUMIF('M5-ICPI'!H5:H24,">0",'M5-ICPI'!H5:H24),"0,0%") -> 0,0% | E16: =IF('DATA-EJES'!D4>=85,"🔵 EXCELENCIA",IF('DATA-EJES'!D4>=70,"🟢 GESTIÓN POR MANDATO",IF('DATA-EJES'!D4>=40,"🟠 TRANSICIÓN CRÍTICA",IF('DATA-EJES'!D4>=20,"🔴 GESTIÓN POR OCURRENCIA","⬛ RUPTURA TOTAL")))) -> 🔴 GESTIÓN POR OCURRENCIA
A17: SOCIAL | B17: =TEXT('DATA-EJES'!D5,"0,0")&" %" -> 51,7 % | C17: =REPT("█",ROUND('DATA-EJES'!D5/5,0))&REPT("░",20-ROUND('DATA-EJES'!D5/5,0))&" "&TEXT('DATA-EJES'!D5,"0,0")&" %" -> ██████████░░░░░░░░░░ 51,7 % | D17: =TEXT(SUMIF('M5-ICPI'!B5:B24,"SOCIAL",'M5-ICPI'!H5:H24)/SUMIF('M5-ICPI'!H5:H24,">0",'M5-ICPI'!H5:H24),"0,0%") -> 0,0% | E17: =IF('DATA-EJES'!D5>=85,"🔵 EXCELENCIA",IF('DATA-EJES'!D5>=70,"🟢 GESTIÓN POR MANDATO",IF('DATA-EJES'!D5>=40,"🟠 TRANSICIÓN CRÍTICA",IF('DATA-EJES'!D5>=20,"🔴 GESTIÓN POR OCURRENCIA","⬛ RUPTURA TOTAL")))) -> 🟠 TRANSICIÓN CRÍTICA | F17: Estado | G17: n
A18: AMBIENTAL | B18: =TEXT('DATA-EJES'!D6,"0,0")&" %" -> 44,9 % | C18: =REPT("█",ROUND('DATA-EJES'!D6/5,0))&REPT("░",20-ROUND('DATA-EJES'!D6/5,0))&" "&TEXT('DATA-EJES'!D6,"0,0")&" %" -> █████████░░░░░░░░░░░ 44,9 % | D18: =TEXT(SUMIF('M5-ICPI'!B5:B24,"AMBIENTAL",'M5-ICPI'!H5:H24)/SUMIF('M5-ICPI'!H5:H24,">0",'M5-ICPI'!H5:H24),"0,0%") -> 17,8% | E18: =IF('DATA-EJES'!D6>=85,"🔵 EXCELENCIA",IF('DATA-EJES'!D6>=70,"🟢 GESTIÓN POR MANDATO",IF('DATA-EJES'!D6>=40,"🟠 TRANSICIÓN CRÍTICA",IF('DATA-EJES'!D6>=20,"🔴 GESTIÓN POR OCURRENCIA","⬛ RUPTURA TOTAL")))) -> 🟠 TRANSICIÓN CRÍTICA | F18: ✅ Evidencia completa | G18: =COUNTIFS('M4-AUDIT'!X5:X24,1,'M4-AUDIT'!Y5:Y24,">="&0.8) -> 1 | H18: =COUNTIFS('M4-AUDIT'!X5:X24,1,'M4-AUDIT'!Y5:Y24,">="&0.99) -> 0
A19: ECONÓMICO | B19: =TEXT('DATA-EJES'!D7,"0,0")&" %" -> 70,0 % | C19: =REPT("█",ROUND('DATA-EJES'!D7/5,0))&REPT("░",20-ROUND('DATA-EJES'!D7/5,0))&" "&TEXT('DATA-EJES'!D7,"0,0")&" %" -> ██████████████░░░░░░ 70,0 % | D19: =TEXT(SUMIF('M5-ICPI'!B5:B24,"ECONÓMICO",'M5-ICPI'!H5:H24)/SUMIF('M5-ICPI'!H5:H24,">0",'M5-ICPI'!H5:H24),"0,0%") -> 0,0% | E19: =IF('DATA-EJES'!D7>=85,"🔵 EXCELENCIA",IF('DATA-EJES'!D7>=70,"🟢 GESTIÓN POR MANDATO",IF('DATA-EJES'!D7>=40,"🟠 TRANSICIÓN CRÍTICA",IF('DATA-EJES'!D7>=20,"🔴 GESTIÓN POR OCURRENCIA","⬛ RUPTURA TOTAL")))) -> 🟢 GESTIÓN POR MANDATO | F19: ⚠️ Evidencia parcial | G19: =COUNTIF('M4-AUDIT'!X5:X24,1)-COUNTIFS('M4-AUDIT'!X5:X24,1,'M4-AUDIT'!Y5:Y24,">="&0.8) -> 7 | H19: =COUNTIF('M4-AUDIT'!X5:X24,1)-COUNTIFS('M4-AUDIT'!X5:X24,1,'M4-AUDIT'!Y5:Y24,">="&0.99) -> 8
A20: INSTITUCIONAL | B20: =TEXT('DATA-EJES'!D8,"0,0")&" %" -> 60,2 % | C20: =REPT("█",ROUND('DATA-EJES'!D8/5,0))&REPT("░",20-ROUND('DATA-EJES'!D8/5,0))&" "&TEXT('DATA-EJES'!D8,"0,0")&" %" -> ████████████░░░░░░░░ 60,2 % | D20: =TEXT(SUMIF('M5-ICPI'!B5:B24,"INSTITUCIONAL",'M5-ICPI'!H5:H24)/SUMIF('M5-ICPI'!H5:H24,">0",'M5-ICPI'!H5:H24),"0,0%") -> 0,0% | E20: =IF('DATA-EJES'!D8>=85,"🔵 EXCELENCIA",IF('DATA-EJES'!D8>=70,"🟢 GESTIÓN POR MANDATO",IF('DATA-EJES'!D8>=40,"🟠 TRANSICIÓN CRÍTICA",IF('DATA-EJES'!D8>=20,"🔴 GESTIÓN POR OCURRENCIA","⬛ RUPTURA TOTAL")))) -> 🟠 TRANSICIÓN CRÍTICA | F20: ❌ Sin evidencia | G20: =20-COUNTIF('M4-AUDIT'!X5:X24,1) -> 12 | H20: =20-COUNTIF('M4-AUDIT'!X5:X24,1) -> 12
A21: △ TOP 5 METAS CRÍTICAS · Mayores brechas de integridad ICPI · Vi=0 o Ti<50% · Prioridad de acción inmediata POA 2025
A23: Nº | B23: COD-META PDOT | C23: BRECHA (pp) | D23: DESCRIPCIÓN / ÁREA CRÍTICA | E23: ACCIÓN REQUERIDA
A24: 1 | B24: PDOT.SC.OE2.M1.01 | C24: −100 pp | D24: Centro de Salud Tipo C · Ri=1.5 · Vi=0 | E24: Convenio MSP urgente · SERCOP · POA 2025
A25: 2 | B25: PDOT.SC.OE2.M3.01 | C25: −100 pp | D25: Unidad Médica Móvil · Ri=1.5 · Vi=0 | E25: Registro vehicular SERCOP · Contrato formal
A26: 3 | B26: PDOT.SC.PI.M5.01 | C26: −100 pp | D26: Central Monitoreo/Cámaras · Ri=1.0 · Vi=0 | E26: Proceso contratación · Especificaciones técnicas
A27: 4 | B27: PDOT.SC.OE2.M4.01 | C27: −90 pp | D27: Guarderías Nocturnas · Ri=1.0 · Ti=0 | E27: Convenio MIES · CIBV · Reformular POA
A28: 5 | B28: PDOT.AS.OE1.M2.02 | C28: −75 pp | D28: Nuevo Camal Municipal · Ri=1.0 · Ti=0,25 | E28: Activar proceso SERCOP · Asignación presupuesto
A30: ≡ ESTADO DOCUMENTAL · Distribución de evidencia forense · n=20 metas PDOT · Ver MAD · MEC · MUAF
A31: ESTADO DOCUMENTAL | B31: n ACTUAL | C31: n META | D31: COBERTURA
A32: ✅ Evidencia completa (Vi=1 · Ti≥80%) | B32: =COUNTIFS('M5-ICPI'!E5:E24,1,'M5-ICPI'!F5:F24,">="&0.8) -> 5 | C32: 20 | D32: ="Ejección plena · "&TEXT(COUNTIFS('M4-AUDIT'!X5:X24,1,'M4-AUDIT'!Y5:Y24,">="&0.8)/20,"0,0%")&" de la muestra · Ver MAD" -> Ejección plena · 5,0% de la muestra · Ver MAD
A33: ⚠️ Evidencia parcial (Vi=1 · Ti<80%) | B33: =COUNTIF('M5-ICPI'!E5:E24,1)-COUNTIFS('M5-ICPI'!E5:E24,1,'M5-ICPI'!F5:F24,">="&0.8) -> 10 | C33: 0 | D33: ="Avance parcial · "&TEXT((COUNTIF('M4-AUDIT'!X5:X24,1)-COUNTIFS('M4-AUDIT'!X5:X24,1,'M4-AUDIT'!Y5:Y24,">="&0.8))/20,"0,0%")&" · Ti pendiente · Ver CEDULAS" -> Avance parcial · 35,0% · Ti pendiente · Ver CEDULAS
A34: ❌ Sin evidencia (Vi=0) | B34: =20-COUNTIF('M5-ICPI'!E5:E24,1) -> 5 | C34: 0 | D34: ="Sin trazabilidad · "&TEXT((20-COUNTIF('M4-AUDIT'!X5:X24,1))/20,"0,0%")&" · Riesgo ICPI · Ver VERIF" -> Sin trazabilidad · 60,0% · Riesgo ICPI · Ver VERIF
A36: ="◈ SIAP-ICPI · GAD Municipal Montecristi · ICPI = "&TEXT('M5-ICPI'!G29,"0,00")&" % · "&IF('M5-ICPI'!G29>=85,"🔵 EXCELENCIA",IF('M5-ICPI'!G29>=70,"🟢 GESTIÓN POR MANDATO",IF('M5-ICPI'!G29>=40,"🟠 TRANSICIÓN CRÍTICA",IF('M5-ICPI'!G29>=20,"🔴 GESTIÓN POR OCURRENCIA","⬛ RUPTURA TOTAL"))))&" · Meta 2027: 100 % · Brecha: "&TEXT('M5-ICPI'!G29-100,"0,00")&" pp" -> ◈ SIAP-ICPI · GAD Municipal Montecristi · ICPI = 38,28 % · 🔴 GESTIÓN POR OCURRENCIA · Meta 2027: 100 % · Brecha: -61,72 pp
A39: 📊 PANEL 5 — CUMPLIMIENTO METAS PDOT POR AÑO · Evolución 2023-2027 · Fuente: Q-SIL + F-EDS + L-PDOT
A40: AÑO | B40: METAS PROGRAMADAS | C40: METAS EJECUTADAS (Ti≥80%) | D40: % CUMPLIMIENTO | E40: ESTADO
A41: 2023 | B41: 12 | C41: 6 | D41: =IF(B41=0,0,C41/B41) -> 0.5 | E41: =IF(C41=0,"Sin ejecución — "&B41&" metas programadas",IF(D41>=1,"✅ Completado — "&C41&"/"&B41&" metas al 100%",IF(D41>=0.8,"🟢 En buen ritmo — "&C41&"/"&B41&" (±80%)",IF(D41>=0.5,"En curso — "&TEXT(D41,"0%")&" metas completadas","🔴 Rezago — "&TEXT(D41,"0%")&" · Requiere acción")))) -> En curso — 50% metas completadas
A42: 2024 | B42: 16 | C42: 8 | D42: =IF(B42=0,0,C42/B42) -> 0.5 | E42: =IF(C42=0,"Sin ejecución — "&B42&" metas programadas",IF(D42>=1,"✅ Completado — "&C42&"/"&B42&" metas al 100%",IF(D42>=0.8,"🟢 En buen ritmo — "&C42&"/"&B42&" (±80%)",IF(D42>=0.5,"En curso — "&TEXT(D42,"0%")&" metas completadas","🔴 Rezago — "&TEXT(D42,"0%")&" · Requiere acción")))) -> En curso — 50% metas completadas
A43: 2025 | B43: 18 | C43: 0 | D43: =IF(B43=0,0,C43/B43) -> 0 | E43: =IF(C43=0,"Por iniciar — "&B43&" metas planificadas",IF(D43>=1,"✅ Completado — "&C43&"/"&B43&" metas al 100%",IF(D43>=0.5,"En curso — "&TEXT(D43,"0%")&" metas completadas","🔴 Rezago — Requiere acción urgente"))) -> Por iniciar — 18 metas planificadas
A44: 2026 | B44: 10 | C44: 0 | D44: =IF(B44=0,0,C44/B44) -> 0 | E44: =IF(C44=0,"Por iniciar — "&B44&" metas planificadas","En curso — "&C44&"/"&B44&" completadas") -> Por iniciar — 10 metas planificadas
A45: 2027 | B45: 8 | C45: 0 | D45: =IF(B45=0,0,C45/B45) -> 0 | E45: =IF(C45=0,"Cierre PDOT Plan Bicentenario — "&B45&" metas","Ejecutado — "&C45&"/"&B45&" completadas") -> Cierre PDOT Plan Bicentenario — 8 metas
...

Sheet M-TECH-GAD
A1: QUADRUM v1.0 · M-TECH-GAD · Configuración Institucional · GAD Municipal Montecristi · Protocolo ALFARO VIRTUS
A2: =HYPERLINK("#'M-INDEX'!A1","⌂ INDICE") -> ⌂ INDICE | B2: =HYPERLINK("#'M1-ITME'!A1","M1") -> M1 | C2: =HYPERLINK("#'M2-PDOT'!A1","M2") -> M2 | D2: =HYPERLINK("#'M3-MAO'!A1","M3") -> M3 | E2: =HYPERLINK("#'M4-AUDIT'!A1","M4") -> M4 | F2: =HYPERLINK("#'M5-ICPI'!A1","M5") -> M5 | G2: =HYPERLINK("#'M6-FEDS'!A1","M6") -> M6 | H2: =HYPERLINK("#'M7-PROSP'!A1","M7") -> M7 | I2: =HYPERLINK("#'DATA-POA'!A1","DATA-POA") -> DATA-POA | J2: =HYPERLINK("#'DATA-CNE'!A1","DATA-CNE") -> DATA-CNE | K2: =HYPERLINK("#'DATA-ORG'!A1","DATA-ORG") -> DATA-ORG | L2: =HYPERLINK("#'M-DASHBOARD'!A1","DASH") -> DASH
A3: Capa: Control > Configuración Institucional · Solo Administrador · SIAP-ICPI §1.1
A4: 🔷 CONFIGURACIÓN INSTITUCIONAL · Solo Administrador · Parámetros base del instrumento
A5: PARÁMETRO | B5: 🟢 VALOR ACTIVO (Montecristi) | C5: EDITABLE (⚫ Sí / ⚫ No) | D5: DESCRIPCIÓN | E5: BASE LEGAL | F5: IMPACTO EN MODELO | G5: FECHA ULT.ACTUALIZ. | H5: RESPONSABLE ACTUALIZ.
A6: NOMBRE_GAD | B6: Gobierno Autónomo Descentralizado Municipal de Montecristi | C6: ⚫ Sí | D6: Nombre oficial completo del GAD Municipal | E6: CRE Art.264 + COOTAD Art.53 | F6: Todos los títulos, headers y exports del modelo | G6: 28/02/2026 | H6: Dir. Planificación
A7: CANTON | B7: Montecristi | C7: ⚫ Sí | D7: Nombre del cantón | E7: COOTAD Art.53 | F7: Dashboard y reportes | G7: 28/02/2026 | H7: Dir. Planificación
A8: PROVINCIA | B8: Manabí | C8: ⚫ Sí | D8: Provincia del cantón | E8: División político-administrativa | F8: Metadata y exports | G8: 28/02/2026 | H8: Dir. Planificación
A9: PAIS | B9: Ecuador | C9: ⚫ No | D9: País (fijo para este modelo) | E9: — | F9: Metadata | G9: 28/02/2026 | H9: —
A10: CLASE_GAD | B10: Municipal / Cantonal | C10: ⚫ No | D10: Clase según COOTAD — este modelo es para GADs Municipales | E10: COOTAD Art.53 | F10: Determina competencias y presupuesto tipo | G10: 28/02/2026 | H10: —
A11: CODIGO_INEC | B11: 130101 | C11: ⚫ Sí | D11: Código INEC del cantón (6 dígitos) | E11: Clasificación territorial INEC | F11: SIGAD, SIGPIP, eSIGEF | G11: 28/02/2026 | H11: Dir. Planificación
A12: ALCALDE | B12: Por confirmar — GAD Montecristi | C12: ⚫ Sí | D12: Nombre del Alcalde/Alcaldesa vigente | E12: COOTAD Art.60 | F12: Firmas y actos administrativos | G12: 28/02/2026 | H12: Secretaría Alcaldía
A14: 🔶 SECCIÓN B — PARÁMETROS PDOT Y EVALUACIÓN · Ajustar al período PDOT y muestra del GAD destino
A15: PERIODO_PDOT | B15: 2023-2027 | C15: ⚫ Sí | D15: Período del PDOT vigente — determina horizonte de evaluación | E15: COOTAD Art.295 | F15: A-PDOT, M-POA, todas las metas | G15: 28/02/2026 | H15: Dir. Planificación
A16: N_METAS | B16: 20 | C16: ⚫ Sí | D16: Número de metas en la muestra estratégica. Cambiar si el GAD tiene más o menos metas auditables. | E16: SIAP-ICPI §3.2 | F16: E1-ICPI (rango fórmulas), B-PONDER (ΣPi=1) | G16: 28/02/2026 | H16: Dir. Planificación
A17: N_EJES | B17: 5 | C17: ⚫ Sí | D17: Número de ejes estratégicos del PDOT | E17: COOTAD Art.295 | F17: H2-EJES, B-PONDER | G17: 28/02/2026 | H17: Dir. Planificación
A18: META_PDOT_2027 | B18: 1 | C18: Benchmark primario del modelo. Ti=1.0 = meta PDOT cumplida al 100% al cierre 2027
A19: ICM_SIGAD_REF | B19: 0.9225 | C19: ICM SIGAD 2023 — solo comparativo §4.2. Benchmark del modelo es Meta PDOT 2027 = 100% | D19: ICM oficial SIGAD más reciente. Actualizar con ICM 2024 cuando esté disponible. | E19: SIGAD-SNP | F19: PARAMS B6, brecha ICPI vs ICM, F-BI | G19: 28/02/2026 | H19: Dir. Planificación
A20: AÑO_ICM_REF | B20: 2023 | C20: 🔵 Sí | D20: Año del índice SIGAD comparativo §4.2. Actualizar junto con ICM_BASE si cambia. | E20: SIGAD-SNP | F20: PARAMS, Dashboard | G20: 28/02/2026 | H20: Dir. Planificación
A21: N_DIRECCIONES | B21: 13 | C21: 🔵 Sí | D21: Número de direcciones en el orgánico. Actualizar con Estatuto Orgánico real. | E21: Estatuto Orgánico GAD | F21: X-ORGANICO, Y-EVAL-DIR, Ci | G21: 28/02/2026 | H21: Dir. Planificación
A22: N_SERVIDORES | B22: ~120 (aprox) | C22: 🔵 Sí | D22: Total servidores públicos en nómina. Base para Z-EVAL-SP completo. | E22: LOSEP + RRHH GAD | F22: Z-EVAL-SP (escalabilidad QUADRUM) | G22: 28/02/2026 | H22: Dir. RRHH
A23: PRESUP_PDOT_USD | B23: 122857648 | C23: 🔵 Sí | D23: Presupuesto total PDOT n=20 metas en USD. Actualizar con cédulas eSIGEF. | E23: PDOT Plan Bicentenario + eSIGEF | F23: L-CEDULAS, B-PONDER, Pi | G23: 28/02/2026 | H23: Dir. Financiera
A25: 🔶 SECCIÓN C — ESCALA LOSEP OFICIAL · Norma Técnica MDT · NO modificar sin cambio normativo
A26: UMBRAL_EXCELENTE | B26: 0.96 | C26: ⚫ No | D26: IED ≥ 96% → Felicitación pública + registro SIITH | E26: LOSEP Art.78 + NT MDT | F26: Y-EVAL-DIR col I, Z-EVAL-SP col N, F-EDS | G26: 28/02/2026 | H26: —
A27: UMBRAL_MUY_BUENO | B27: 0.85 | C27: ⚫ No | D27: IED 85-95.99% → Reconocimiento + SIITH | E27: LOSEP Art.77 + NT MDT | F27: Ídem | G27: 28/02/2026 | H27: —
A28: UMBRAL_SATISFACTORIO | B28: 0.7 | C28: ⚫ No | D28: IED 70-84.99% → Sin acción (aprobado) | E28: LOSEP Art.76 + NT MDT | F28: Ídem | G28: 28/02/2026 | H28: —
A29: UMBRAL_REGULAR | B29: 0.6 | C29: ⚫ No | D29: IED 60-69.99% → Plan mejora 90 días | E29: LOSEP Art.77 + NT MDT | F29: Ídem | G29: 28/02/2026 | H29: —
A30: UMBRAL_INACEPTABLE | B30: 0 | C30: ⚫ No | D30: IED <60% → Sumario administrativo LOSEP Art.80 | E30: LOSEP Art.80 + COA Art.196 | F30: Ídem | G30: 28/02/2026 | H30: —
A32: 🔶 SECCIÓN D — PARÁMETROS CININ Y EVALUACIÓN PRESUPUESTARIA · Ajustar si el GAD tiene menos silos activos (ej: GAD rural sin SIGAD completo)
A33: CININ_SILOS | B33: 6 | C33: ⚫ No | D33: 🟢 Número de silos CININ activos. 6 = modelo completo. Ver TRAZABILIDAD. | E33: SIAP-ICPI §3.4 | F33: D-MAD cols Q:V, Vi_CADENA | G33: 28/02/2026 | H33: SIAP-ICPI
A34: MODO_CININ | B34: COMPLETO | C34: 🔵 Sí | D34: COMPLETO = 6 silos. LITE = 3 silos (GADs rurales sin SIGAD/CPCCS). MÍNIMO = S1+S4 (solo PDOT+cédula). | E34: SIAP-ICPI §3.4 | F34: D-MAD lógica Vi_CADENA | G34: 28/02/2026 | H34: Dir. Planificación
A35: Ti_BASE | B35: Devengado/Codif | C35: ⚫ No | D35: Ti = Devengado / Codificado vigente (no inicial PDOT). Ver L-CEDULAS. | E35: COPFP Art.111+118 | F35: L-CEDULAS col K, D-MAD col T | G35: 28/02/2026 | H35: Dir. Financiera
A36: CORTE_SEMESTRAL | B36: Junio | C36: 🔵 Sí | D36: Mes del corte semestral de evaluación LOSEP Art.77 | E36: LOSEP Art.77 | F36: Y-EVAL-DIR, Z-EVAL-SP | G36: 28/02/2026 | H36: Dir. RRHH
A37: CORTE_ANUAL | B37: Diciembre | C37: ⚫ No | D37: Mes del corte anual obligatorio LOSEP | E37: LOSEP Art.77 | F37: Y-EVAL-DIR, Z-EVAL-SP | G37: 28/02/2026 | H37: —
A39: 🔶 SECCIÓN E — ESTADO DE IMPLEMENTACIÓN Y S · Hoja de ruta para el modelo al 10/10
A40: ESTATUTO_ORGANICO | C40: 🔵 Actualizar | D40: Actualizar con Estatuto Orgánico vigente GAD Montecristi → Hoja ORGANICO refleja estructura administrativa oficial según normativa vigente | E40: X-ORGANICO | F40: 🟠 Alta | G40: Dir. Planificación + Alcaldía
A41: SIITH_INTEGRACION | C41: 🔵 Implementar | D41: Protocolo exportación Z-EVAL-SP → sistema SIITH MDT para validez jurídica evaluación LOSEP | E41: Z-EVAL-SP | F41: 🟠 Alta | G41: Dir. RRHH + Dir. TI
A42: ICM_2024 | C42: 🔵 Actualizar | D42: Actualizar ICM_BASE con valor oficial SIGAD 2024 cuando esté disponible (Q1 2025) | E42: PARAMS B6 | F42: 🟠 Alta | G42: Dir. Planificación
A43: CEDULAS_REALES | C43: 🔵 Actualizar | D43: Ingresar CUPs reales y codificado vigente real de eSIGEF en L-CEDULAS (actualmente aproximado) | E43: L-CEDULAS | F43: 🟠 Alta | G43: Dir. Financiera
A44: EVAL_SEMESTRAL | C44: 🔵 Implementar | D44: Módulo corte junio: copia Y-EVAL-DIR + Z-EVAL-SP a hojas Y-EVAL-DIR-S1 y Z-EVAL-SP-S1 | E44: Y/Z-EVAL | F44: 🟡 Media | G44: Dir. RRHH
...

Sheet M-TECH-PARAMS
A1: QUADRUM v1.0 · M-TECH-PARAMS · Parámetros Globales · Umbrales · Constantes del Sistema · Protocolo de Integridad Forense ALFARO VIRTUS
A2: =HYPERLINK("#'M-INDEX'!A1","⌂ INDICE") -> ⌂ INDICE | B2: =HYPERLINK("#'M1-ITME'!A1","M1") -> M1 | C2: =HYPERLINK("#'M2-PDOT'!A1","M2") -> M2 | D2: =HYPERLINK("#'M3-MAO'!A1","M3") -> M3 | E2: =HYPERLINK("#'M4-AUDIT'!A1","M4") -> M4 | F2: =HYPERLINK("#'M5-ICPI'!A1","M5") -> M5 | G2: =HYPERLINK("#'M6-FEDS'!A1","M6") -> M6 | H2: =HYPERLINK("#'M7-PROSP'!A1","M7") -> M7 | I2: =HYPERLINK("#'DATA-POA'!A1","DATA-POA") -> DATA-POA | J2: =HYPERLINK("#'DATA-CNE'!A1","DATA-CNE") -> DATA-CNE | K2: =HYPERLINK("#'DATA-ORG'!A1","DATA-ORG") -> DATA-ORG | L2: =HYPERLINK("#'M-DASHBOARD'!A1","DASH") -> DASH
A3: Capa: Control > Parámetros Globales del Sistema · SIAP-ICPI §1.2
A4: 🔷 PARÁMETROS TÉCNICOS · Rangos de Integridad Programática · Categorías ICPI · Factores globales del modelo
A5: ━━ SECCIÓN ❶ BENCHMARK PDOT 2027 — Meta de cumplimiento y comparativo ICM-SIGAD
A6: Meta PDOT 2027 (benchmark primario) | B6: 1 | C6: Cada meta debe alcanzar Ti=1.0 al cierre del Plan Bicentenario 2027 — fuente PDOT §4 | D6: Valor oficial ICM 2023 del SIGAD — fuente: Informe rendicion de cuentas RDC 2023 + SIGAD-SNP linea Montecristi | E6: 23/02/2025
A7: ICM SIGAD 2023 (comparativo — auto-reporte) | B7: =92.25&" %" -> 92,25 % | C7: Auto-reporte SIGAD. NO es el benchmark. Útil para cuantificar diferencial forense §4.2 | D7: : SIGAD libera dato oficial ICM 2024 primer trimestre 2025 — actualizar con valor oficial
A8: Brecha PDOT (ICPI − Meta 2027) pp | B8: =TEXT(('M5-ICPI'!G26-1)*100,"0,00")&" pp" -> -100,00 pp | C8: Brecha primaria del modelo. Meta=100% PDOT 2027. Negativa = incumplimiento §3.6 | D8: ICPI − ICM en puntos porcentuales. Fuente: E2-RESUL (motor ICPI) vs. ICM SIGAD 2023 (celda B6 PARAMS) | E8: 23/02/2025
A9: ICPI Calculado (%) | B9: ='M5-ICPI'!G29 -> 38.283014 | C9: E2-RESUL!B6 * 100 | D9: SIAP-ICPI · 36 hojas · CININ 6 silos · Ti corregido (S4=eSIGEF autoridad) · Cadena PDOT→POA→PAC→Cédula→SIGAD→CPCCS · ORGANICO+EVAL-DIR+EVAL-SP · CONFIG-GAD · CEDULAS · SEMESTRAL · ITME inventario técnico | E9: 23/02/2025
A10: ━━ SECCIÓN ➊ ICPI — Motor Algorítmico Central
A11: ICPI Final (decimal) | B11: ='DATA-RESULTADOS'!C6 -> 0.40003606 | C11: E2-RESUL!B6 | D11: Motor E1-ICPI: Σ(Pi×Ri×Vi×Ei×Ti×Ci) ÷ Σ(Pi×Ri) · Ci incorporado §3.7.1 | E11: 23/02/2025
A12: ICPI Final (%) | B12: ='DATA-RESULTADOS'!C6*100 -> 40.003606 | C12: E2-RESUL!B6 * 100 | D12: ICPI expresado en % para comparación con ICM y Rangos de Integridad Programática (AVEP) | E12: 23/02/2025
A13: Rango de Integridad (AVEP) | B13: 🟡 TRANSICIÓN CRÍTICA | C13: E2-RESUL!B8 | D13: ⭐ Rangos de Integridad (AVEP): Ruptura | Ocurrencia | Transición Crítica | Mandato | Excelencia | E13: 23/02/2025
A14: Σ Numerador Σ(Pi×Ri×Vi×Ei×Ti) | B14: ='M5-ICPI'!G25 -> 0.40896482 | C14: E2-RESUL!B4 | D14: Numerador de la fórmula multifactorial ICPI · Incluye Ci por meta (C-MAO → D-MAD col P → E1-ICPI col I) · Ci incorporado §3.7.1 | E14: 23/02/2025
A15: Σ Denominador Σ(Pi×Ri) | B15: =SUM('M5-ICPI'!H5:H24) -> 1.0682671 | C15: E2-RESUL!B5 | D15: Denominador de la fórmula multifactorial ICPI | E15: 23/02/2025
A16: Interpretación cualitativa | B16: ='DATA-RESULTADOS'!B8 -> Transición Crítica 🟡 | C16: E2-RESUL!B9 | D16: Texto narrativo del Rango de Integridad activo (AVEP) | E16: 23/02/2025
A18: ━━ SECCIÓN ➋ MUESTRA — Universo y Representatividad
A19: N — Universo PDOT (metas estrategicas Plan Bicentenario) | B19: 20 | C19: A-PDOT (n=20 metas seleccionadas por mayor impacto presupuestario y competencia GAD) | D19: Total metas PDOT en muestra estrategica SIAP-ICPI. Fuente: A-PDOT Plan Bicentenario 2023-2027 | E19: 22/02/2025
A20: n — Muestra estrategica PDOT activa | B20: =COUNTA('M4-AUDIT'!A5:A24) -> 20 | C20: A-PDOT (conteo metas activas con evidencia auditada) | D20: Muestra SEPP: n=20 de N=67 por mayor impacto presupuestario | E20: 22/02/2025
A21: Representatividad financiera (%) | B21: =IFERROR(B23/B22, 0) -> 0 | C21: B3-VALREP | D21: La muestra n=20 representa el 87.2% del presupuesto total ($13.875M / $15.91M) | E21: 22/02/2025
A22: Presupuesto muestra n=20 ($) | B22: {=IFERROR(SUMPRODUCT(('M2-PLAN-Pi'!E13:E32>0)*'M2-PLAN-Pi'!E13:E32),0)} -> 0 | C22: A-PDOT col M (Presupuesto PDOT por meta) — suma metas n=20 | D22: Suma de presupuestos de las 20 metas muestra (USD) | E22: 46075
A23: Presupuesto con trazabilidad ($) | B23: {=IFERROR(SUMPRODUCT(('M4-AUDIT'!F5:F24=1)*('M2-PLAN-Pi'!E13:E32>0)*'M2-PLAN-Pi'!E13:E32),0)} -> 0 | C23: D-MAD (Vi=1) | D23: Inversión trazada documentalmente (metas Vi=1) | E23: 23/02/2025
A25: ━━ SECCIÓN ➉ VARIABLES Vi / Ei / Ti / Ci — Estado Documental y Atribución Orgánica
A26: Metas con Vi=1 (soporte documental) | B26: =COUNTIF('M4-AUDIT'!F5:F24,1) -> 15 | C26: D-MAD (conteo Vi=1) | D26: Metas con respaldo forense verificado en sistemas oficiales | E26: 23/02/2025
A27: Metas con Vi=0 (sin soporte) | B27: =COUNTIF('M4-AUDIT'!F5:F24,0) -> 5 | C27: D-MAD (conteo Vi=0) | D27: Metas sin respaldo — Vi=0 anula completamente la contribución al ICPI | E27: 23/02/2025
A28: Metas con ejecución completa (Vi=1 y Ti=1) | B28: {=SUMPRODUCT(('M4-AUDIT'!F5:F24=1)*('M4-AUDIT'!H5:H24>=1))} -> 4 | C28: D-MAD | D28: TER-01 (Maquinaria), TER-18 (Señalética), SOC-03 (Geriátrico), INS-05 (Catastro) | E28: 23/02/2025
A29: Metas con evidencia parcial (Vi=1 y Ti<1) | B29: {=SUMPRODUCT(('M4-AUDIT'!F5:F24=1)*('M4-AUDIT'!H5:H24<1))} -> 11 | C29: D-MAD | D29: Con respaldo pero ejecución incompleta — Ti entre 0.25 y 0.90 | E29: 23/02/2025
A30: Metas con Ci<1.0 (control parcial) | B30: =COUNTIF('M4-AUDIT'!P5:P24,"<1") -> 3 | C30: C-MAO / D-MAD col P | D30: Ci∈{1.0;0.9;0.75;0.5} según dueño del proceso (Estatuto Orgánico + COOTAD §3.7.1). 13 GAD directo Ci=1.0 | 7 adscritos Ci=0.9. Fuente: C-MAO → D-MAD col P (VLOOKUP) → E1-ICPI col I. D-MAD: col C=Silo Oficial §3.4 | col D=Área Temática. | E30: 27/02/2026
A31: IED Promedio (F-EDS) — Score desempeño | B31: =IFERROR(AVERAGE('M6-FEDS'!J7:J26),"-") -> 30.4625 | C31: F-EDS!J7:J26 | D31: IED promedio de las 20 metas (0-100) · F-EDS triangula Estatuto Orgánico→POA→PAC→Cédula · OUTPUT §3.7.1 | E31: 27/02/2026
A32: ❌ Direcciones con IED INACEPTABLE (0-19) | B32: =COUNTIF('M6-FEDS'!F30:F41,"RUPTURA TOTAL") -> 0 | C32: F-EDS!F30:F41 | D32: Direcciones con RUPTURA TOTAL (IED=0) · Sumario administrativo LOSEP Art.80 + COOTAD Art.339 | E32: 27/02/2026
A33: ━━ SECCIÓN ➍ ICPI POR EJE ESTRATÉGICO
A34: ICPI Eje TERRITORIAL (%) | B34: ='DATA-EJES'!D4 -> 25.761436 | C34: H2-EJES!D4 | D34: 9 metas territoriales | Mayor eje por peso presupuestario (61.0%) | E34: 23/02/2025
A35: ICPI Eje SOCIAL (%) | B35: ='DATA-EJES'!D5 -> 51.686758 | C35: H2-EJES!D5 | D35: 6 metas sociales | Eje con mayor cantidad de Vi=0 (4 sin soporte) | E35: 23/02/2025
A36: ICPI Eje AMBIENTAL (%) | B36: ='DATA-EJES'!D6 -> 44.931664 | C36: H2-EJES!D6 | D36: 2 metas ambientales | Vi=1 en ambas pero Ti bajo (0.27-0.36) | E36: 23/02/2025
A37: ICPI Eje ECONÓMICO (%) | B37: ='DATA-EJES'!D7 -> 70 | C37: H2-EJES!D7 | D37: 1 meta económica | ECO-12 con Vi=1 Ti=0.30 — Playa San José | E37: 23/02/2025
A38: ICPI Eje INSTITUCIONAL (%) | B38: ='DATA-EJES'!D8 -> 60.15129 | C38: H2-EJES!D8 | D38: 2 metas institucionales | Eje mejor documentado (85.8% ICPI) | E38: 23/02/2025
A40: ━━ SECCIÓN ➎ BRECHA DE INTEGRIDAD — ICPI vs Meta PDOT 2027 (primaria) + Diferencial SIGAD (comparativo)
A41: Brecha PDOT (ICPI vs Meta 2027) pp | B41: =TEXT(('M5-ICPI'!G26-1)*100,"0,00")&" pp" -> -100,00 pp | C41: E2-RESUL!B6*100 - A-PDOT!AA5 | D41: ICPI auditado (41,53%) vs ICM oficial SIGAD (92,25%) → Diferencial de Integridad SIGAD §4.2 · Ci incorporado | E41: 23/02/2025
A42: Brecha promedio por meta (pp) | B42: =TEXT(('M5-ICPI'!G26-1)*100/20,"0,00")&" pp" -> -5,00 pp | C42: Déficit promedio de cada meta respecto a Ti=1.0 — señal de dispersión §3.6 | D42: Brecha promedio simple por meta (F-BI fila PROMEDIO) | E42: 23/02/2025
A43: Diferencial forense SIGAD − ICPI (§4.2 comparativo) | B43: =TEXT((0.9225-'M5-ICPI'!G26)*100,"0,00")&" pp" -> 92,25 pp | C43: ICM SIGAD auto-reportado (92,25%) supera ICPI auditado (41,53%) en +50,72 pp → Erosión del Compromiso §4.2 | D43: Metas donde ICPI auditado < ICM SIGAD reportado | E43: 23/02/2025
...

Sheet M1-ITME
A1: QUADRUM v1.0 · M1-ITME · Inventario Técnico de Metas Estratégicas · GAD Municipal Montecristi | Z1: ⌂ ÍNDICE
A2: =HYPERLINK("#'M-INDEX'!A1","⌂ INDICE") -> ⌂ INDICE | B2: =HYPERLINK("#'M1-ITME'!A1","◉ M1") -> ◉ M1 | C2: =HYPERLINK("#'M2-PDOT'!A1","M2") -> M2 | D2: =HYPERLINK("#'M3-MAO'!A1","M3") -> M3 | E2: =HYPERLINK("#'M4-AUDIT'!A1","M4") -> M4 | F2: =HYPERLINK("#'M5-ICPI'!A1","M5") -> M5 | G2: =HYPERLINK("#'M6-FEDS'!A1","M6") -> M6 | H2: =HYPERLINK("#'M7-PROSP'!A1","M7") -> M7 | I2: =HYPERLINK("#'DATA-POA'!A1","DATA-POA") -> DATA-POA | J2: =HYPERLINK("#'DATA-CNE'!A1","DATA-CNE") -> DATA-CNE | K2: =HYPERLINK("#'DATA-ORG'!A1","DATA-ORG") -> DATA-ORG | L2: =HYPERLINK("#'DATA-RESULTADOS'!A1","RESULT") -> RESULT | M2: =HYPERLINK("#'M-DASHBOARD'!A1","DASH") -> DASH
A3: #
A4: N° | B4: COD-PDOT (Inventario) | C4: SISTEMA PDOT | D4: EJE ESTRATÉGICO | E4: PROGRAMA PDOT | F4: SUBPROGRAMA | G4: PROYECTO / DESCRIPCIÓN SINTÉTICA | H4: PROYECTO ESTRATÉGICO PDOT | I4: OBJETIVO DE GESTIÓN | J4: PRESUP. PDOT ($) | K4: EN MUESTRA SIAP-ICPI | L4: COD-META MUESTRA | M4: ALINEACIÓN PDOT | N4: OBSERVACIÓN / CANDIDATOS PARA MUESTRA FUTURA
A5: 1 | B5: PDOT.FA.OE1.PV.01 | C5: Físico Ambiental | D5: AMBIENTAL | E5: Áreas verdes y zonas de Protección | F5: Nuevos parques y zonas de protección | G5: Red Verde urbana: Parque Las Pampas + Parque Cárcel Simón Bolívar + Parque Estancia Las Palmas | H5: Parques Inter barriales / Parque Las Pampas / Parque Cárcel Simón Bolívar | I5: Incrementar áreas de protección e índice verde urbano | J5: 709999.54 | K5: No | L5: — | M5: ⚠️ PARCIAL | N5: Candidato próxima muestra — parques urbanos IE PDOT
A6: 2 | B6: PDOT.FA.OE1.PV.02 | C6: Físico Ambiental | D6: AMBIENTAL | E6: Áreas verdes y zonas de Protección | F6: Mantenimiento de áreas verdes | G6: Mantenimiento arbolado urbano y Rehabilitación Parque Colorado | H6: Rehabilitación Parque Colorado | I6: Incrementar áreas de protección e índice verde urbano | J6: 25000 | K6: No | L6: — | M6: ✅ ALINEADA | N6: Operación recurrente — presupuesto bajo
A7: 3 | B7: PDOT.FA.OE1.MA.01 | C7: Físico Ambiental | D7: AMBIENTAL | E7: Áreas verdes / Recuperación ambiental | F7: Recuperación y preservación ambiental | G7: Proyecto Ecoturístico Manglar Vivo Playa San José (Muestra M18) | H7: Recuperación y manejo sustentable Playa San José / Repotenciación manglar costero | I7: Incrementar áreas de protección e índice verde urbano | J7: 75000 | K7: ✅ Sí | L7: PDOT.EP.OE5.M1.01 | M7: ✅ ALINEADA | N7: M18 en muestra — Vi=1 Ti=0.30 — BDE Premio Verde
A8: 4 | B8: PDOT.FA.OE2.MA.01 | C8: Físico Ambiental | D8: AMBIENTAL | E8: Ambiente | F8: Mitigación Ambiental | G8: Albergue/Centro recuperación fauna urbana — componente manglar y biodiversidad | H8: Estudio diseño Centro de Recuperación de paso de Fauna | I8: Cumplir el desarrollo de la planificación ambiental | J8: 137136.64 | K8: ✅ Sí | L8: PDOT.AM.SC.M3.01 | M8: ⚠️ PARCIAL | N8: M17 en muestra — Vi=1 Ti=0.35 — vincular Manglar Vivo
A9: 5 | B9: PDOT.FA.OE3.GR.01 | C9: Físico Ambiental | D9: AMBIENTAL | E9: Gestión del Riesgo | F9: Infraestructura de mitigación + Zonas evacuación | G9: Gestión del riesgo: reforestación quebradas + señalética + sistema alerta temprana | H9: Reforestación zonas susceptibles amenazas / Sistema integrado alerta temprana | I9: Reducir el riesgo fortaleciendo la infraestructura y mejorando la resiliencia | J9: 950000 | K9: No | L9: — | M9: ⚠️ PARCIAL | N9: Candidato próxima muestra — Ri=1.5 resiliencia climática
A10: 6 | B10: PDOT.FA.OE4.AH.01 | C10: Físico Ambiental | D10: AMBIENTAL | E10: Aseo e Higiene | F10: Recolección de desechos sólidos | G10: Gestión integral desechos sólidos: recolección y transporte | H10: Repotenciación y adquisición de recolectores de basura | I10: Promover prácticas sostenibles de manejo de desechos | J10: 5001962.8 | K10: No | L10: — | M10: ✅ ALINEADA | N10: EP Aseo gestiona — candidato muestra futura
A11: 7 | B11: PDOT.FA.OE4.AH.02 | C11: Físico Ambiental | D11: AMBIENTAL | E11: Aseo e Higiene | F11: Tratamiento de desechos — Relleno Sanitario | G11: Nuevo relleno sanitario cantonal — construcción y operación EP Aseo | H11: Construcción nuevo relleno sanitario cantón Montecristi | I11: Promover prácticas sostenibles de manejo de desechos | J11: 748782.57 | K11: ✅ Sí | L11: PDOT.AM.OE3.M2.01 | M11: ⚠️ PARCIAL | N11: M12 en muestra — Vi=1 Ti=0.30 — regularización MAATE
A12: 8 | B12: PDOT.AS.OE1.AP.01 | C12: Asentamientos Humanos | D12: TERRITORIAL | E12: Agua y saneamiento | F12: Agua Potable — Redes + Acueducto CAF | G12: Cobertura agua potable: ampliación redes + Acueducto CAF 30.000m³/día — mayor ítem PDOT | H12: Gestión Construcción Acueducto CAF $45.6M — 30.000m³/día | I12: Ampliar y mejorar la cobertura de equipamientos, áreas verdes y servicios básicos | J12: 46904874 | K12: ✅ Sí | L12: PDOT.AS.OE1.M1.01 | M12: ✅ ALINEADA | N12: M1 en muestra — Pi=0.112 — Vi=1 Ti=0.85 — CAF contraparte
A13: 9 | B13: PDOT.AS.OE1.AP.02 | C13: Asentamientos Humanos | D13: TERRITORIAL | E13: Agua y saneamiento | F13: Agua Potable — Reservorios y Captación Rural | G13: Reservorios y captación agua rural: tanques reserva comunas + continuidad servicio | H13: Nueva infraestructura captación y tratamiento agua — reservorios rurales | I13: Ampliar y mejorar la cobertura de servicios básicos | J13: 0 | K13: ✅ Sí | L13: PDOT.AS.OE1.M1.03 | M13: 🔴 BAJA | N13: M20 en muestra — Ti=0.25 — BDE reservorios rurales
A14: 10 | B14: PDOT.AS.OE1.SN.01 | C14: Asentamientos Humanos | D14: TERRITORIAL | E14: Agua y saneamiento | F14: Saneamiento — Alcantarillado + PTAR | G14: Alcantarillado sanitario: Fase I PROGAPSA + Colector Principal + PTAR | H14: Fase I Alcantarillado BEI-PROGAPSA + PTAR Montecristi | I14: Ampliar y mejorar la cobertura de servicios básicos | J14: 1269859.5 | K14: ✅ Sí | L14: PDOT.AS.OE1.M1.02 | M14: ✅ ALINEADA | N14: M2 en muestra — Pi=0.231 — mayor Pi — BDE-PROGAPSA
A15: 11 | B15: PDOT.FA.OE4.PT.01 | C15: F. Ambiental / As. Humanos | D15: AMBIENTAL | E15: Agua y saneamiento / Ambiente | F15: PTAR — Planta de Tratamiento de Aguas Residuales | G15: PTAR: Planta Tratamiento Aguas Residuales Montecristi + Aníbal San Andrés | H15: Construcción Colector Principal y PTAR Montecristi + Aníbal San Andrés (CELEC/BDE) | I15: Gestión integral de aguas residuales — componente ambiental crítico | J15: 0 | K15: ✅ Sí | L15: PDOT.AM.OE3.M1.01 | M15: ⚠️ PARCIAL | N15: M9 en muestra — Pi=0.045 — Ti=0.40 — CELEC/BDE PTAR
A16: 12 | B16: PDOT.AS.OE1.PL.01 | C16: Asentamientos Humanos | D16: TERRITORIAL | E16: Agua y saneamiento | F16: Pluvial — Redes de drenaje urbano | G16: Redes pluviales: estudios técnicos para ampliación de cobertura | H16: Estudios técnicos proyección nuevas redes pluviales urbanas | I16: Ampliar y mejorar la cobertura de servicios básicos | J16: 10000 | K16: No | L16: — | M16: ⚠️ PARCIAL | N16: Presupuesto mínimo — solo estudios — complementa M1+M2
... A39: 35 | B39: PDOT.PI.OE6.PC.01 | C39: Político Institucional | D39: INSTITUCIONAL | E39: Participación y cogestión ciudadana | F39: Construcción participativa ciudadana | G39: Participación ciudadana: asambleas + cabildo + rendición cuentas + cogestión | H39: Sistema construcción participativa planificación + Rendición Cuentas CPCCS | I39: Fomentar la participación ciudadana y la construcción colaborativa | J39: 137900 | K39: No | L39: — | M39: ✅ ALINEADA | N39: Vinculado LOTAIP Art.7 lit.m y CPCCS — rendición cuentas
A40: Σ | B40: TOTALES UNIVERSO · 35 programas/proyectos en 5 sistemas
A41: 🔷 SECCIÓN B — MUESTRA SIAP-ICPI · n=20 Metas Estratégicas · Datos oficiales PDOT Plan Bicentenario 2023-2027 · Fuente: Plan Plurianual Inversiones + PAC 2023-2024 · Pi = Presup_i / ΣPresup (fuente maestra: PDOT!L4:L23)
A42: Nº | B42: CÓD. PDOT (Oficial) | C42: SISTEMA PDOT | D42: META ESTRATÉGICA PDOT (descripción oficial) | E42: Pi (peso pres.) | F42: Ri (relevancia) | G42: Vi (evidencia) | H42: Ti (ejecución) | I42: PROYECTO ESTRATÉGICO PDOT (descripción sintética) | J42: PRESUP. PDOT ($) (fuente: PDOT!L) | K42: INDICADOR META 2027 (oficial PDOT) | L42: RESPONSABLE INSTITUCIONAL | M42: ALINEACIÓN PDOT | N42: ESTADO POA 2025 / RECOMENDACIÓN
A43: 1 | B43: ='M2-PDOT'!B4 -> PDOT.AS.VL.M1.01 | C43: ='M2-PDOT'!C4 -> Asentamientos Humanos | D43: ='M2-PDOT'!D4 -> Mantenimiento de vías urbanas para el acceso de los barrios del cantón | E43: ='M2-PDOT'!E4 -> 0.33155843 | F43: ='M2-PDOT'!F4 -> 1 | G43: ='M2-PDOT'!G4 -> 1 | H43: ='M2-PDOT'!H4 -> 0.25 | I43: Integración ejes viales estratégicos — bacheo, pavimentación y mantenimiento vías urbanas y rurales | J43: ='M2-PDOT'!L4 -> 10892761 | K43: Kilómetros de vías intervenidas / mantenidas por año | L43: ='M2-PDOT'!K4 -> Dir. Obras Públicas | M43: ='M2-PDOT'!N4 -> ✅ ALINEADA | N43: Vi=1 Ti=0.90 ✅ — PAC $3.1M ejecutado — Pi=0.330 mayor muestra
A44: 2 | B44: ='M2-PDOT'!B5 -> PDOT.SC.OE2.M1.01 | C44: ='M2-PDOT'!C5 -> Socio Cultural | D44: ='M2-PDOT'!D5 -> Desarrollo del Bienestar Integral para Montecristi | E44: ='M2-PDOT'!E5 -> 0.17737919 | F44: ='M2-PDOT'!F5 -> 1 | G44: ='M2-PDOT'!G5 -> 1 | H44: ='M2-PDOT'!H5 -> 0.65 | I44: Centro de Salud Tipo C «Nacer Aquí» + Repotenciación Clínica de Diálisis — gestión convenio MSP-ULEAM | J44: ='M2-PDOT'!L5 -> 5827477 | K44: % avance físico construcción / convenio MSP suscrito | L44: ='M2-PDOT'!K5 -> Patronato Municipal | M44: ='M2-PDOT'!N5 -> ✅ ALINEADA | N44: Vi=0 CRÍTICO — convenio MSP pendiente — Δ ICPI +9.1pp si Vi→1
A45: 3 | B45: ='M2-PDOT'!B6 -> PDOT.AM.OE3.M2.01 | C45: ='M2-PDOT'!C6 -> Ambiental | D45: ='M2-PDOT'!D6 -> Gestión Integral de Desechos Sólidos | E45: ='M2-PDOT'!E6 -> 0.15225184 | F45: ='M2-PDOT'!F6 -> 1 | G45: ='M2-PDOT'!G6 -> 1 | H45: ='M2-PDOT'!H6 -> 0.75 | I45: Gestión integral desechos sólidos: recolección, transporte y relleno sanitario — Empresa de Aseo Municipal EP | J45: ='M2-PDOT'!L6 -> 5001962.8 | K45: Toneladas procesadas por año / cobertura recolección cantonal | L45: ='M2-PDOT'!K6 -> Dir. Gestión Ambiental | M45: ='M2-PDOT'!N6 -> ✅ ALINEADA | N45: Vi=1 Ti=0.30 — Ordenanza Aseo sancionada — iniciar MAATE
A46: 4 | B46: ='M2-PDOT'!B7 -> PDOT.AS.OE1.M2.01 | C46: ='M2-PDOT'!C7 -> Asentamientos Humanos | D46: ='M2-PDOT'!D7 -> Fortalecimiento estratégico de equipamiento público comercial y administrativo | E46: ='M2-PDOT'!E7 -> 0.051556596 | F46: ='M2-PDOT'!F7 -> 1 | G46: ='M2-PDOT'!G7 -> 0 | H46: ='M2-PDOT'!H7 -> 0.1 | I46: Terminal Terrestre Ciudad Bicentenario + Estación Bomberil Chirijos + Infocentros | J46: ='M2-PDOT'!L7 -> 1693800 | K46: % avance físico construcción / índice equipamiento urbano CUP | L46: ='M2-PDOT'!K7 -> Dir. Planificación | M46: ='M2-PDOT'!N7 -> ⚠️ PARCIAL | N46: Vi=1 Ti=0.45 — estudios diseño POA 2025 — RDC 2023
A47: 5 | B47: ='M2-PDOT'!B8 -> PDOT.SC.OE2.M4.01 | C47: ='M2-PDOT'!C8 -> Socio Cultural | D47: ='M2-PDOT'!D8 -> Proyecto Integral de Desarrollo y Apoyo Comunitario | E47: ='M2-PDOT'!E8 -> 0.049038304 | F47: ='M2-PDOT'!F8 -> 1 | G47: ='M2-PDOT'!G8 -> 1 | H47: ='M2-PDOT'!H8 -> 0.2 | I47: CDI + Guarderías Nocturnas + Montecristi Solidario — Protección derechos grupos vulnerables | J47: ='M2-PDOT'!L8 -> 1611066 | K47: % avance físico / Nº beneficiarios grupos vulnerables atendidos | L47: ='M2-PDOT'!K8 -> Dir. Planificación | M47: ='M2-PDOT'!N8 -> ⚠️ PARCIAL | N47: Vi=0 Ti=0 CRÍTICO — convenio MIES CIBV nocturno pendiente
A48: 6 | B48: ='M2-PDOT'!B9 -> PDOT.AS.OE1.M1.02 | C48: ='M2-PDOT'!C9 -> Asentamientos Humanos | D48: ='M2-PDOT'!D9 -> Gestión para la construcción de nueva infraestructura de tratamiento de aguas residuales | E48: ='M2-PDOT'!E9 -> 0.038652516 | F48: ='M2-PDOT'!F9 -> 1.5 | G48: ='M2-PDOT'!G9 -> 0 | H48: ='M2-PDOT'!H9 -> 0 | I48: Fase I Alcantarillado BDE-PROGAPSA + Colector Principal + PTAR Montecristi | J48: ='M2-PDOT'!L9 -> 1269859.5 | K48: Metros lineales de red construida / % cobertura alcantarillado cantonal | L48: ='M2-PDOT'!K9 -> Dir. Agua Potable y Alcantarillado | M48: ='M2-PDOT'!N9 -> 🔴 BAJA | N48: Vi=1 Ti=0.75 — BDE-PROGAPSA activar Fase I
A49: 7 | B49: ='M2-PDOT'!B10 -> PDOT.PI.OE4.M1.01 | C49: ='M2-PDOT'!C10 -> Político Institucional | D49: ='M2-PDOT'!D10 -> Implementación de la Transformación digital de los procedimientos institucionales | E49: ='M2-PDOT'!E10 -> 0.037123042 | F49: ='M2-PDOT'!F10 -> 1 | G49: ='M2-PDOT'!G10 -> 1 | H49: ='M2-PDOT'!H10 -> 1 | I49: Transformación digital trámites + Catastro Integrado alfanumérico-gráfico + WiFi público + ERP municipal | J49: ='M2-PDOT'!L10 -> 1219611.3 | K49: % digitalización trámites / nivel conocimiento gestión municipal al 55% | L49: ='M2-PDOT'!K10 -> Dir. TICs | M49: ='M2-PDOT'!N10 -> ✅ ALINEADA | N49: Vi=1 Ti=0.70 ✅ — ERP $636K ejecutado — plataforma ciudadana pendiente
A50: 8 | B50: ='M2-PDOT'!B11 -> PDOT.AV.OE1.M1.01 | C50: ='M2-PDOT'!C11 -> Asentamientos Humanos | D50: ='M2-PDOT'!D11 -> Recuperación integral de los espacios públicos | E50: ='M2-PDOT'!E11 -> 0.027234953 | F50: ='M2-PDOT'!F11 -> 1 | G50: ='M2-PDOT'!G11 -> 1 | H50: ='M2-PDOT'!H11 -> 0.9 | I50: Parque Las Pampas Fase I + Red Verde + canchas recreativas — Recuperación espacios públicos | J50: ='M2-PDOT'!L11 -> 894755.8 | K50: Índice verde urbano / Nº parques nuevos construidos | L50: ='M2-PDOT'!K11 -> Dir. Planificación | M50: ='M2-PDOT'!N11 -> ✅ ALINEADA | N50: Vi=1 Ti=0.50 — Parque Las Pampas Fase I en POA 2025
A51: 9 | B51: ='M2-PDOT'!B12 -> PDOT.AM.OE3.M1.01 | C51: ='M2-PDOT'!C12 -> Ambiental | D51: ='M2-PDOT'!D12 -> Implementación de Infraestructura civil para la mitigación y reducción de impactos ante la susceptib | E51: ='M2-PDOT'!E12 -> 0.025568273 | F51: ='M2-PDOT'!F12 -> 1.5 | G51: ='M2-PDOT'!G12 -> 0 | H51: ='M2-PDOT'!H12 -> 0.3 | I51: Construcción Colector Principal y PTAR Montecristi + Aníbal San Andrés — financiamiento CELEC/BDE | J51: ='M2-PDOT'!L12 -> 840000 | K51: Nº plantas y estaciones de bombeo operativas / % avance PTAR | L51: ='M2-PDOT'!K12 -> Dir. Planificación | M51: ='M2-PDOT'!N12 -> 🔴 BAJA | N51: Vi=1 Ti=0.40 — CELEC/BDE gestionar — estudios PTAR POA 2025
A52: 10 | B52: ='M2-PDOT'!B13 -> PDOT.FA.OE4.AH.02 | C52: ='M2-PDOT'!C13 -> Físico Ambiental | D52: ='M2-PDOT'!D13 -> Mejorando la capacidad de disposición final de desechos sólidos | E52: ='M2-PDOT'!E13 -> 0.022791758 | F52: ='M2-PDOT'!F13 -> 1 | G52: ='M2-PDOT'!G13 -> 1 | H52: ='M2-PDOT'!H13 -> 0.4 | I52: Nuevo relleno sanitario cantonal — construcción y operación EP Aseo — regularización MAATE | J52: ='M2-PDOT'!L13 -> 748782.57 | K52: Capacidad disposición final (toneladas/año) / proceso MAATE iniciado | L52: ='M2-PDOT'!K13 -> Dir. Gestión Ambiental | M52: ='M2-PDOT'!N13 -> ⚠️ PARCIAL | N52: Vi=1 Ti=0.30 — proceso MAATE pendiente — EIA en POA 2025
A53: 11 | B53: ='M2-PDOT'!B14 -> PDOT.FA.OE1.PV.01 | C53: ='M2-PDOT'!C14 -> Físico Ambiental | D53: ='M2-PDOT'!D14 -> Desarrollo de la red Verde y recuperación del espacio público | E53: ='M2-PDOT'!E14 -> 0.018567422 | F53: ='M2-PDOT'!F14 -> 1 | G53: ='M2-PDOT'!G14 -> 1 | H53: ='M2-PDOT'!H14 -> 0.5 | I53: Red Verde urbana: Parque Las Pampas + Parque Cárcel Simón Bolívar + Parque Estancia Las Palmas | J53: ='M2-PDOT'!L14 -> 609999.54 | K53: Índice verde urbano consolidado / Hectáreas nuevas áreas protegidas | L53: ='M2-PDOT'!K14 -> Dir. Gestión Ambiental | M53: ='M2-PDOT'!N14 -> ⚠️ PARCIAL | N53: Vi=1 Ti=0.50 — incluir POA 2025 como IE PDOT — complementa M8
A54: 12 | B54: ='M2-PDOT'!B15 -> PDOT.PI.OE4.M2.01 | C54: ='M2-PDOT'!C15 -> Político Institucional | D54: ='M2-PDOT'!D15 -> Fortalecimiento del Sistema de Información Territorial Municipal | E54: ='M2-PDOT'!E15 -> 0.018292146 | F54: ='M2-PDOT'!F15 -> 1 | G54: ='M2-PDOT'!G15 -> 0 | H54: ='M2-PDOT'!H15 -> 0 | I54: SIT Municipal + LIDAR + geomática institucional — Catastro Integrado alfanumérico-gráfico | J54: ='M2-PDOT'!L15 -> 600955.83 | K54: % actualización catastral / cobertura SIG cantonal | L54: ='M2-PDOT'!K15 -> Dir. TICs | M54: ='M2-PDOT'!N15 -> 🔴 BAJA | N54: Vi=1 Ti=1.0 ✅ CUMPLIDA — LIDAR $250K — integrar en SIG
... A62: 20 | B62: ='M2-PDOT'!B23 -> PDOT.FA.OE2.MA.01 | C62: ='M2-PDOT'!C23 -> 0 | D62: ='M2-PDOT'!D23 -> 0 | E62: ='M2-PDOT'!E23 -> 0 | F62: ='M2-PDOT'!F23 -> 0 | G62: ='M2-PDOT'!G23 -> 0 | H62: ='M2-PDOT'!H23 -> 0 | I62: Albergue/Centro recuperación fauna urbana + Ordenanza Nº017-2024 — componente manglar y biodiversidad | J62: ='M2-PDOT'!L23 -> 0 | K62: Nº animales atendidos / castraciones realizadas / ordenanza vigente | L62: ='M2-PDOT'!K23 -> 0 | M62: ='M2-PDOT'!N23 -> 0 | N62: Vi=1 Ti=0.35 — 172 castraciones + Ordenanza 017-2024 — vincular Manglar
A63: Σ | B63: TOTALES MUESTRA · n=20 metas · ΣPi = 1.000 ✅ · Fuente maestra: PDOT hoja
A64: 📋 | B64: CRITERIO DE EXCLUSIÓN (COOTAD Art. 234 · COPYFP Art. 292)

Sheet M2-PDOT
A1: QUADRUM v1.0 · M2-PDOT · Base Legal Operativa de Metas PDOT 2023-2027 · GAD Municipal Montecristi
A2: =HYPERLINK("#'M-INDEX'!A1","⌂ INDICE") -> ⌂ INDICE | B2: =HYPERLINK("#'M1-ITME'!A1","M1") -> M1 | C2: =HYPERLINK("#'M2-PDOT'!A1","◉ M2-PDOT") -> ◉ M2-PDOT | D2: =HYPERLINK("#'M3-MAO'!A1","M3") -> M3 | E2: =HYPERLINK("#'M4-AUDIT'!A1","M4") -> M4 | F2: =HYPERLINK("#'M5-ICPI'!A1","M5") -> M5 | G2: =HYPERLINK("#'M6-FEDS'!A1","M6") -> M6 | H2: =HYPERLINK("#'M7-PROSP'!A1","M7") -> M7 | I2: =HYPERLINK("#'DATA-POA'!A1","DATA-POA") -> DATA-POA | J2: =HYPERLINK("#'DATA-CNE'!A1","DATA-CNE") -> DATA-CNE | K2: =HYPERLINK("#'DATA-ORG'!A1","DATA-ORG") -> DATA-ORG | L2: =HYPERLINK("#'M-DASHBOARD'!A1","DASH") -> DASH
A3: Capa: Base/Plan > Metas Estratégicas PDOT Plan Bicentenario 2023-2027 · Base: COOTAD Art.295 | B3: CÓD. PDOT / ID_META | C3: SISTEMA | D3: META ESTRATÉGICA | E3: Pi | F3: Ri | G3: Vi | H3: Ti | I3: Ci | J3: Ei | K3: RESPONSABLE | L3: PRESUPUESTO | M3: INDICADOR | N3: ALINEACIÓN PDOT
A4: 1 | B4: PDOT.AS.VL.M1.01 | C4: Asentamientos Humanos | D4: Mantenimiento de vías urbanas para el acceso de los barrios del cantón | E4: =L4/L$24 -> 0.33155843 | F4: 1 | G4: =IFERROR(VLOOKUP(B4,'M4-AUDIT'!$A$5:$H$24,MATCH("Vi",'M4-AUDIT'!$A$4:$H$4,0),0),0) -> 1 | H4: =IFERROR(VLOOKUP(B4,'M4-AUDIT'!$A$5:$H$24,MATCH("Ti (H)",'M4-AUDIT'!$A$4:$H$4,0),0),0) -> 0.25 | I4: 1 | J4: 1 | K4: Dir. Obras Públicas | L4: 10892761 | M4: Kilómetros de vías intervenidas | N4: ✅ ALINEADA
A5: 2 | B5: PDOT.SC.OE2.M1.01 | C5: Socio Cultural | D5: Desarrollo del Bienestar Integral para Montecristi | E5: =L5/L$24 -> 0.17737919 | F5: 1 | G5: =IFERROR(VLOOKUP(B5,'M4-AUDIT'!$A$5:$H$24,MATCH("Vi",'M4-AUDIT'!$A$4:$H$4,0),0),0) -> 1 | H5: =IFERROR(VLOOKUP(B5,'M4-AUDIT'!$A$5:$H$24,MATCH("Ti (H)",'M4-AUDIT'!$A$4:$H$4,0),0),0) -> 0.65 | I5: 0.9 | J5: 1 | K5: Patronato Municipal | L5: 5827477 | M5: Porcentaje de avance físico | N5: ✅ ALINEADA
A6: 3 | B6: PDOT.AM.OE3.M2.01 | C6: Ambiental | D6: Gestión Integral de Desechos Sólidos | E6: =L6/L$24 -> 0.15225184 | F6: 1 | G6: =IFERROR(VLOOKUP(B6,'M4-AUDIT'!$A$5:$H$24,MATCH("Vi",'M4-AUDIT'!$A$4:$H$4,0),0),0) -> 1 | H6: =IFERROR(VLOOKUP(B6,'M4-AUDIT'!$A$5:$H$24,MATCH("Ti (H)",'M4-AUDIT'!$A$4:$H$4,0),0),0) -> 0.75 | I6: 1 | J6: 1 | K6: Dir. Gestión Ambiental | L6: 5001962.8 | M6: Toneladas procesadas/año | N6: ✅ ALINEADA
A7: 4 | B7: PDOT.AS.OE1.M2.01 | C7: Asentamientos Humanos | D7: Fortalecimiento estratégico de equipamiento público comercial y administrativo | E7: =L7/L$24 -> 0.051556596 | F7: 1 | G7: =IFERROR(VLOOKUP(B7,'M4-AUDIT'!$A$5:$H$24,MATCH("Vi",'M4-AUDIT'!$A$4:$H$4,0),0),0) -> 0 | H7: =IFERROR(VLOOKUP(B7,'M4-AUDIT'!$A$5:$H$24,MATCH("Ti (H)",'M4-AUDIT'!$A$4:$H$4,0),0),0) -> 0.1 | I7: 1 | J7: 1 | K7: Dir. Planificación | L7: 1693800 | M7: Porcentaje de avance físico | N7: ⚠️ PARCIAL
A8: 5 | B8: PDOT.SC.OE2.M4.01 | C8: Socio Cultural | D8: Proyecto Integral de Desarrollo y Apoyo Comunitario | E8: =L8/L$24 -> 0.049038304 | F8: 1 | G8: =IFERROR(VLOOKUP(B8,'M4-AUDIT'!$A$5:$H$24,MATCH("Vi",'M4-AUDIT'!$A$4:$H$4,0),0),0) -> 1 | H8: =IFERROR(VLOOKUP(B8,'M4-AUDIT'!$A$5:$H$24,MATCH("Ti (H)",'M4-AUDIT'!$A$4:$H$4,0),0),0) -> 0.2 | I8: 1 | J8: 1 | K8: Dir. Planificación | L8: 1611066 | M8: Porcentaje de avance físico | N8: ⚠️ PARCIAL
A9: 6 | B9: PDOT.AS.OE1.M1.02 | C9: Asentamientos Humanos | D9: Gestión para la construcción de nueva infraestructura de tratamiento de aguas residuales | E9: =L9/L$24 -> 0.038652516 | F9: 1.5 | G9: =IFERROR(VLOOKUP(B9,'M4-AUDIT'!$A$5:$H$24,MATCH("Vi",'M4-AUDIT'!$A$4:$H$4,0),0),0) -> 0 | H9: =IFERROR(VLOOKUP(B9,'M4-AUDIT'!$A$5:$H$24,MATCH("Ti (H)",'M4-AUDIT'!$A$4:$H$4,0),0),0) -> 0 | I9: 1 | J9: 1 | K9: Dir. Agua Potable y Alcantarillado | L9: 1269859.5 | M9: Metros lineales de red construida | N9: 🔴 BAJA
A10: 7 | B10: PDOT.PI.OE4.M1.01 | C10: Político Institucional | D10: Implementación de la Transformación digital de los procedimientos institucionales | E10: =L10/L$24 -> 0.037123042 | F10: 1 | G10: =IFERROR(VLOOKUP(B10,'M4-AUDIT'!$A$5:$H$24,MATCH("Vi",'M4-AUDIT'!$A$4:$H$4,0),0),0) -> 1 | H10: =IFERROR(VLOOKUP(B10,'M4-AUDIT'!$A$5:$H$24,MATCH("Ti (H)",'M4-AUDIT'!$A$4:$H$4,0),0),0) -> 1 | I10: 1 | J10: 1 | K10: Dir. TICs | L10: 1219611.3 | M10: Porcentaje de avance físico | N10: ✅ ALINEADA
A11: 8 | B11: PDOT.AV.OE1.M1.01 | C11: Asentamientos Humanos | D11: Recuperación integral de los espacios públicos | E11: =L11/L$24 -> 0.027234953 | F11: 1 | G11: =IFERROR(VLOOKUP(B11,'M4-AUDIT'!$A$5:$H$24,MATCH("Vi",'M4-AUDIT'!$A$4:$H$4,0),0),0) -> 1 | H11: =IFERROR(VLOOKUP(B11,'M4-AUDIT'!$A$5:$H$24,MATCH("Ti (H)",'M4-AUDIT'!$A$4:$H$4,0),0),0) -> 0.9 | I11: 1 | J11: 1 | K11: Dir. Planificación | L11: 894755.8 | M11: Porcentaje de avance físico | N11: ✅ ALINEADA
A12: 9 | B12: PDOT.AM.OE3.M1.01 | C12: Ambiental | D12: Implementación de Infraestructura civil para la mitigación y reducción de impactos ante la susceptib | E12: =L12/L$24 -> 0.025568273 | F12: 1.5 | G12: =IFERROR(VLOOKUP(B12,'M4-AUDIT'!$A$5:$H$24,MATCH("Vi",'M4-AUDIT'!$A$4:$H$4,0),0),0) -> 0 | H12: =IFERROR(VLOOKUP(B12,'M4-AUDIT'!$A$5:$H$24,MATCH("Ti (H)",'M4-AUDIT'!$A$4:$H$4,0),0),0) -> 0.3 | I12: 1 | J12: 1 | K12: Dir. Planificación | L12: 840000 | M12: Porcentaje de avance físico | N12: 🔴 BAJA
